2022-02-26 15:39:24,358 - base_log.py[line:31] - ERROR: 执行用例1的时候报错:
2022-02-26 15:39:24,725 - base_log.py[line:31] - ERROR: 执行用例2的时候报错:
2022-02-26 15:39:25,759 - base_log.py[line:31] - ERROR: 执行用例3的时候报错:
2022-02-26 15:39:26,485 - base_log.py[line:31] - ERROR: 执行用例4的时候报错:
2022-02-26 15:39:26,798 - base_log.py[line:31] - ERROR: 执行用例5的时候报错:
2022-02-26 15:39:27,687 - base_log.py[line:31] - ERROR: 执行用例6的时候报错:
2022-02-26 15:39:28,080 - base_log.py[line:31] - ERROR: 执行用例7的时候报错:
2022-02-26 15:39:28,378 - base_log.py[line:31] - ERROR: 执行用例8的时候报错:
2022-02-26 15:39:29,252 - base_log.py[line:31] - ERROR: 执行用例9的时候报错:
2022-02-26 15:39:29,513 - base_log.py[line:31] - ERROR: 执行用例10的时候报错:
2022-02-26 15:39:30,189 - base_log.py[line:31] - ERROR: 执行用例11的时候报错:
